Workbook

Sheet Portfolio
A1: Code | B1: Family | C1: Type | D1: Title VI | E1: Title EN | F1: Min Level | G1: Level Name | H1: Prerequisites | I1: Prereq Codes | J1: Scope | K1: Deliverables | L1: MVT | M1: Extension | N1: Tools | O1: Status | P1: Alias HK1_2026_2027 | Q1: Career Relevance
A2: A0-P01 | B2: A0 | C2: P | D2: Thiết kế và tự chế tạo thủ công mạch nguồn DC cơ bản | E2: Design and Manual Fabrication of a Basic DC Power Supply PCB | F2: 0 | G2: Explorer | H2: Điện tử cơ bản; an toàn điện; cẩn thận. | J2: Requirement -> component selection -> schematic -> PCB layout -> manual fabrication -> assembly -> measurement -> debug. | K2: Schematic; PCB layout; PCB tự chế tạo; board lắp ráp; kết quả đo tải/ripple; debugging log. | M2: So sánh hai phương án nguồn hoặc cải thiện ripple/thermal trong phạm vi an toàn. | N2: KiCad/EDA PCB tương đương; dụng cụ làm PCB thủ công; đồng hồ số; oscilloscope/logic analyzer khi phù hợp. | O2: active | Q2: Hardware/PCB engineer; nền tảng thực hành cho mọi hướng phần cứng.
A3: A0-P02 | B3: A0 | C3: P | D3: Thiết kế và chế tạo mạch logic tổ hợp trên PCB | E3: Design and Manual PCB Implementation of a Combinational Logic Circuit | F3: 0 | G3: Explorer | H3: Logic tổ hợp + điện tử cơ bản. | J3: Boolean -> gates/ICs -> schematic -> PCB -> fabrication -> test. | K3: Truth table; schematic; PCB; board thật; measurement; failure-fix evidence. | M3: Đánh giá fan-out/noise margin ở mức minh họa nếu thiết bị cho phép. | N3: KiCad/EDA PCB tương đương; dụng cụ làm PCB thủ công; đồng hồ số; oscilloscope/logic analyzer khi phù hợp. | O3: active | Q3: Hardware/PCB engineer; nền tảng thực hành cho mọi hướng phần cứng.
A4: A0-P03 | B4: A0 | C4: P | D4: Thiết kế và chế tạo bộ đếm số trên PCB | E4: Design and Manual Implementation of a Digital Counter PCB | F4: 0 | G4: Explorer | H4: Logic tuần tự cơ bản. | J4: Clock, counter, reset, display/7-segment và tín hiệu điều khiển. | K4: Schematic; PCB; counter + display hoạt động; test reset/clock; debugging report. | M4: Bổ sung debounce hoặc nhiều mode đếm. | N4: KiCad/EDA PCB tương đương; dụng cụ làm PCB thủ công; đồng hồ số; oscilloscope/logic analyzer khi phù hợp. | O4: active | Q4: Hardware/PCB engineer; nền tảng thực hành cho mọi hướng phần cứng.
A5: A0-P04 | B5: A0 | C5: P | D5: Thiết kế board giao tiếp cảm biến | E5: Design and Manual Fabrication of a Sensor Interface Board | F5: 0 | G5: Explorer | H5: Điện tử cơ bản; biết đọc datasheet. | J5: Sensor -> signal conditioning/interface -> connector/ADC/MCU tùy mức. | K5: Requirement; datasheet note; schematic; PCB; board; measurement. | M5: Calibration hoặc đánh giá noise. | N5: KiCad/EDA PCB tương đương; dụng cụ làm PCB thủ công; đồng hồ số; oscilloscope/logic analyzer khi phù hợp. | O5: active | Q5: Hardware/PCB engineer; nền tảng thực hành cho mọi hướng phần cứng.
A6: A0-P05 | B6: A0 | C6: P | D6: Thiết kế embedded controller board cơ bản | E6: Design of a Basic Microcontroller-Based Embedded Board | F6: 1 | G6: Beginner Engineer | H6: Điện tử; MCU cơ bản; datasheet. | J6: MCU + power + reset + clock + LED/button + UART/sensor connector. | K6: Schematic; PCB; power/reset/clock/I/O; firmware test; board demo. | M6: Bổ sung một peripheral hoặc low-power mode. | N6: KiCad/EDA PCB tương đương; dụng cụ làm PCB thủ công; đồng hồ số; oscilloscope/logic analyzer khi phù hợp. | O6: active | Q6: Hardware/PCB engineer; nền tảng thực hành cho mọi hướng phần cứng.
A7: A0-P06 | B7: A0 | C7: P | D7: Thiết kế PCB mở rộng I/O cho FPGA | E7: Design of a Custom FPGA I/O Expansion Board | F7: 1 | G7: Beginner Engineer | H7: Điện tử + hiểu I/O FPGA ở mức cơ bản. | J7: FPGA development board -> GPIO/SPI/UART -> custom PCB -> sensor/LED/DAC/actuator. | K7: PCB extension; interface test; FPGA demo; documentation. | M7: Thêm protocol hoặc đo timing I/O. | N7: KiCad/EDA PCB tương đương; dụng cụ làm PCB thủ công; đồng hồ số; oscilloscope/logic analyzer khi phù hợp. | O7: active | Q7: Hardware/PCB engineer; nền tảng thực hành cho mọi hướng phần cứng.
A8: A0-I01 | B8: A0 | C8: I | D8: Thực tập thiết kế, chế tạo và kiểm thử phần cứng điện tử | E8: Electronic Hardware Design, Fabrication and Testing Internship | F8: 1 | G8: Beginner Engineer | H8: Hoàn thành ít nhất một project A0-P hoặc năng lực tương đương. | I8: A0-P* | J8: Một board hoàn chỉnh qua requirement-design-build-test-debug-document. | K8: Working board; design files; BOM; measurement; debug log; technical report; legacy package. | M8: Tối ưu revision 2 dựa trên lỗi revision 1. | N8: KiCad/EDA PCB tương đương; dụng cụ làm PCB thủ công; đồng hồ số; oscilloscope/logic analyzer khi phù hợp. | O8: active | Q8: Hardware/PCB engineer; nền tảng thực hành cho mọi hướng phần cứng.
A9: A1-P01 | B9: A1 | C9: P | D9: Thiết kế các mạch logic tổ hợp bằng Verilog | E9: Combinational Logic Design in Verilog | F9: 0 | G9: Explorer | H9: Logic tổ hợp. | J9: MUX/decoder/comparator/ALU nhỏ với exhaustive hoặc directed tests. | K9: RTL; testbench; waveform; short report. | M9: So sánh coding style và synthesis. | N9: Verilog/SystemVerilog; Icarus Verilog/Verilator; GTKWave; Git. | O9: active | Q9: RTL design & verification engineer.
A10: A1-P02 | B10: A1 | C10: P | D10: Thiết kế các mạch tuần tự bằng Verilog | E10: Sequential Logic Design in Verilog | F10: 0 | G10: Explorer | H10: Flip-flop/counter/register. | J10: Counter/shift register/clock divider/sequence detector. | K10: RTL; reset tests; waveform; report. | M10: Thêm parameterization hoặc corner cases. | N10: Verilog/SystemVerilog; Icarus Verilog/Verilator; GTKWave; Git. | O10: active | Q10: RTL design & verification engineer.
A11: A1-P03 | B11: A1 | C11: P | D11: Thiết kế FSM cho một bộ điều khiển số | E11: FSM Design for a Digital Controller | F11: 1 | G11: Beginner Engineer | H11: Logic tuần tự + state diagram. | J11: Traffic/vending/simple controller. | K11: Specification; state diagram; RTL; tests; waveform. | M11: Moore vs Mealy comparison nếu phù hợp. | N11: Verilog/SystemVerilog; Icarus Verilog/Verilator; GTKWave; Git. | O11: active | Q11: RTL design & verification engineer.
A12: A1-P04 | B12: A1 | C12: P | D12: Thiết kế UART transmitter/receiver bằng RTL | E12: RTL Design of a UART Transmitter/Receiver | F12: 1 | G12: Beginner Engineer | H12: RTL cơ bản; timing counter. | J12: TX/RX với baud generator và corner tests. | K12: UART RTL; loopback testbench; waveform; README. | M12: Parameterized baud/data format. | N12: Verilog/SystemVerilog; Icarus Verilog/Verilator; GTKWave; Git. | O12: active | Q12: RTL design & verification engineer.
A13: A1-P05 | B13: A1 | C13: P | D13: Thiết kế synchronous FIFO bằng RTL | E13: RTL Design of a Synchronous FIFO | F13: 1 | G13: Beginner Engineer | H13: RTL; pointer/counter. | J13: Parameterized FIFO và verification. | K13: FIFO RTL; full/empty/overflow/underflow tests; waveform. | M13: Thêm assertions hoặc coverage-like checklist. | N13: Verilog/SystemVerilog; Icarus Verilog/Verilator; GTKWave; Git. | O13: active | Q13: RTL design & verification engineer.
A14: A1-I01 | B14: A1 | C14: I | D14: Thiết kế và kiểm chứng reusable Digital IP Core | E14: Design and Verification of a Reusable Digital IP Core | F14: 1 | G14: Beginner Engineer | H14: A1-P tương đương; Git cơ bản. | I14: A1-P* | J14: UART/SPI/FIFO/PWM/Timer theo engineering workflow. | K14: Specification; reusable RTL; testbench; regression; documentation; repo. | M14: Thêm parameterization và CI. | N14: Verilog/SystemVerilog; Icarus Verilog/Verilator; GTKWave; Git. | O14: active | Q14: RTL design & verification engineer.
A15: A1-T01 | B15: A1 | C15: T | D15: Thiết kế và kiểm chứng một IP số có khả năng tái sử dụng | E15: Design and Verification of a Reusable Digital IP | F15: 2 | G15: Independent Engineering Student | H15: RTL khá; simulation/debug; Git. | I15: A1-P* | J15: Tập trung correctness, corner cases, portability và reuse. | K15: Complete IP; systematic verification; synthesis report; documentation; legacy package. | L15: Specification; Reusable RTL IP; Testbench + regression; Waveform/checklist verification; FPGA demo; User guide cho IP. | M15: FPGA/ASIC implementation hoặc stronger verification. | N15: Verilog/SystemVerilog, Icarus/Verilator/ModelSim, GTKWave, FPGA tool, Git. | O15: active | P15: A4 | Q15: RTL design & verification engineer.
A16: A2-P01 | B16: A2 | C16: P | D16: Thiết kế và so sánh các kiến trúc bộ cộng số | E16: Design and Comparison of Digital Adder Architectures | F16: 1 | G16: Beginner Engineer | H16: Binary arithmetic + RTL. | J16: Ripple-carry / carry-lookahead / carry-select theo bit-width phù hợp. | K16: RTL nhiều architecture; functional tests; synthesis comparison. | M16: Thêm parallel-prefix nếu đủ năng lực. | N16: Verilog/SystemVerilog; Python/MATLAB; FPGA toolchain; Yosys/ASIC flow khi mở rộng. | O16: active | Q16: DSP hardware / datapath design; nền số học cho FPGA-ASIC.
A17: A2-P02 | B17: A2 | C17: P | D17: Thiết kế multiplier fixed-point | E17: Fixed-Point Multiplier Design | F17: 1 | G17: Beginner Engineer | H17: Signed arithmetic; RTL. | J17: Signed fixed-point multiply với scaling và overflow handling. | K17: Reference model; RTL; overflow/truncation tests; synthesis. | M17: Rounding/saturation comparison. | N17: Verilog/SystemVerilog; Python/MATLAB; FPGA toolchain; Yosys/ASIC flow khi mở rộng. | O17: active | Q17: DSP hardware / datapath design; nền số học cho FPGA-ASIC.
A18: A2-P03 | B18: A2 | C18: P | D18: Thiết kế Multiply-Accumulate datapath | E18: Multiply-Accumulate Datapath Design | F18: 1 | G18: Beginner Engineer | H18: Multiplier + accumulator concepts. | J18: Multiplier -> accumulator -> registers/pipeline. | K18: MAC RTL; pipeline tests; resource/timing report. | M18: Resource sharing vs parallel. | N18: Verilog/SystemVerilog; Python/MATLAB; FPGA toolchain; Yosys/ASIC flow khi mở rộng. | O18: active | Q18: DSP hardware / datapath design; nền số học cho FPGA-ASIC.
A19: A2-P04 | B19: A2 | C19: P | D19: Thiết kế bộ lọc FIR bằng RTL | E19: RTL Design of an FIR Filter | F19: 1 | G19: Beginner Engineer | H19: DSP cơ bản; RTL. | J19: Delay line + coefficients + multiply/add. | K19: Floating reference; RTL; fixed-point test; waveform. | M19: Direct vs transposed architecture. | N19: Verilog/SystemVerilog; Python/MATLAB; FPGA toolchain; Yosys/ASIC flow khi mở rộng. | O19: active | Q19: DSP hardware / datapath design; nền số học cho FPGA-ASIC.
A20: A2-I01 | B20: A2 | C20: I | D20: Thiết kế và triển khai datapath DSP fixed-point trên FPGA | E20: Fixed-Point DSP Datapath Design and FPGA Implementation | F20: 2 | G20: Independent Engineering Student | H20: A2-P hoặc tương đương; FPGA cơ bản. | I20: A2-P* | J20: Một datapath DSP hoàn chỉnh và co-verification. | K20: Golden model; RTL; FPGA synthesis; resource/Fmax/latency; report. | M20: Bit-width sweep. | N20: Verilog/SystemVerilog; Python/MATLAB; FPGA toolchain; Yosys/ASIC flow khi mở rộng. | O20: active | Q20: DSP hardware / datapath design; nền số học cho FPGA-ASIC.
A21: A2-T01 | B21: A2 | C21: T | D21: Thiết kế bộ lọc FIR fixed-point trên FPGA và khảo sát ASIC | E21: Fixed-Point FIR Filter Design on FPGA with ASIC Implementation Analysis | F21: 2 | G21: Independent Engineering Student | H21: DSP + RTL + FPGA; Python/MATLAB. | I21: A2-P04 | J21: Floating -> fixed -> RTL -> FPGA -> ASIC feasibility. | K21: Reference; quantization; RTL; FPGA results; ASIC synthesis/physical evidence phù hợp; analysis. | L21: Golden model + test vectors; Fixed-point error analysis; RTL + testbench; FPGA resource/Fmax/latency; ASIC area/timing estimate; Bảng trade-off accuracy - hardware cost. | M21: Architecture comparison hoặc coefficient quantization study. | N21: MATLAB/Python, Verilog, FPGA toolchain, Yosys/LibreLane tùy phạm vi. | O21: active | P21: A3 | Q21: DSP hardware / datapath design; nền số học cho FPGA-ASIC.
A22: A2-T02 | B22: A2 | C22: T | D22: Thiết kế và tối ưu MAC datapath cho FPGA/ASIC | E22: Design and Optimization of a Fixed-Point MAC Datapath for FPGA/ASIC | F22: 2 | G22: Independent Engineering Student | H22: RTL; fixed-point; synthesis. | I22: A2-P03 | J22: Bit width + pipeline + rounding/saturation + resource sharing. | K22: Multiple configurations; PPA/resource/timing; accuracy; report. | L22: Golden model; Parameterized RTL MAC; Verification vectors; PPA/Fmax/latency table; Numerical error analysis. | M22: Pareto/design-space analysis. | N22: Python/MATLAB, Verilog, FPGA tool, synthesis/STA. | O22: active | P22: A9 | Q22: DSP hardware / datapath design; nền số học cho FPGA-ASIC.
A23: A2-T03 | B23: A2 | C23: T | D23: Thiết kế và đánh giá PPA của các kiến trúc bộ cộng số học | E23: Design and PPA Evaluation of Digital Adder Architectures | F23: 2 | G23: Independent Engineering Student | H23: Logic tổ hợp; binary arithmetic; RTL; synthesis/STA cơ bản. | I23: A2-P01 | J23: Triển khai và so sánh các kiến trúc adder theo delay/area trên nhiều bit-width trong cùng điều kiện synthesis/implementation. | K23: RTL các kiến trúc RCA/CLA/carry-select (tùy chọn parallel-prefix); functional-equivalence tests; synthesis/STA cùng constraint; phân tích logic depth/carry propagation; bảng PPA theo bit-width 8/16/32/64. | L23: RTL các adder; Common testbench; Timing/area table theo bit-width; Critical path analysis; Design recommendation. | M23: Thêm parallel-prefix (Kogge-Stone/Brent-Kung) hoặc Pareto analysis theo bit-width. | N23: Verilog, simulator, Yosys/synthesis, OpenSTA/ASIC flow. | O23: active | P23: A8 | Q23: DSP hardware / datapath design; nền số học cho FPGA-ASIC.
A24: A2-R01 | B24: A2 | C24: R | D24: Hardware design-space exploration cho fixed-point datapath | E24: Hardware Design-Space Exploration for Fixed-Point Datapaths | F24: 4 | G24: Undergraduate Researcher | H24: A2-T-level baseline; scripting; controlled experiments. | I24: A2-T* | J24: Quantify accuracy-area-timing-throughput trade-off across architecture/precision. | K24: Reproducible sweep; Pareto analysis; research report/paper-ready figures. | M24: Optimization/search method nếu baseline sweep đã chắc. | N24: Verilog/SystemVerilog; Python/MATLAB; FPGA toolchain; Yosys/ASIC flow khi mở rộng. | O24: active | Q24: DSP hardware / datapath design; nền số học cho FPGA-ASIC.
A25: A3-P01 | B25: A3 | C25: P | D25: Triển khai một Digital IP trên FPGA | E25: FPGA Implementation of a Digital IP | F25: 1 | G25: Beginner Engineer | H25: RTL + simulation. | I25: A1-P* | J25: Take a verified IP to FPGA and test physical I/O. | K25: Bitstream/project; hardware demo; resource/Fmax; README. | M25: Add self-test or measurement. | N25: FPGA vendor tools; Verilog/SystemVerilog; ModelSim/Questa/Icarus/Verilator tùy nền tảng; logic analyzer khi có. | O25: active | Q25: FPGA system engineer.
A26: A3-P02 | B26: A3 | C26: P | D26: FPGA interfacing với peripheral | E26: FPGA Interfacing with a Peripheral | F26: 1 | G26: Beginner Engineer | H26: RTL; basic protocol. | I26: A1-P* | J26: UART/SPI/ADC/sensor/7-segment interface. | K26: Interface RTL; board demo; tests; documentation. | M26: Higher-rate mode or error handling. | N26: FPGA vendor tools; Verilog/SystemVerilog; ModelSim/Questa/Icarus/Verilator tùy nền tảng; logic analyzer khi có. | O26: active | Q26: FPGA system engineer.
A27: A3-P03 | B27: A3 | C27: P | D27: Hệ thống xử lý tín hiệu số trên FPGA | E27: FPGA-Based Digital Signal Processing System | F27: 2 | G27: Independent Engineering Student | H27: A2 basics + FPGA. | I27: A2-P* | J27: FIR/moving average/simple convolution. | K27: Working DSP pipeline; resource/timing; hardware test. | M27: Streaming/pipelining optimization. | N27: FPGA vendor tools; Verilog/SystemVerilog; ModelSim/Questa/Icarus/Verilator tùy nền tảng; logic analyzer khi có. | O27: active | Q27: FPGA system engineer.
A28: A3-I01 | B28: A3 | C28: I | D28: Xây dựng hệ thống FPGA tích hợp nhiều IP | E28: Integration of Multiple IP Cores on FPGA | F28: 2 | G28: Independent Engineering Student | H28: A1 + basic FPGA. | I28: A1-P* | J28: UART -> FIFO -> processing core -> output, hoặc hệ tương đương. | K28: Integrated system; interface tests; demo; documentation. | M28: Add monitoring or CI. | N28: FPGA vendor tools; Verilog/SystemVerilog; ModelSim/Questa/Icarus/Verilator tùy nền tảng; logic analyzer khi có. | O28: active | Q28: FPGA system engineer.
A29: A3-T01 | B29: A3 | C29: T | D29: Thiết kế hệ thống xử lý dữ liệu số pipelined trên FPGA | E29: Design of a Pipelined Digital Processing System on FPGA | F29: 2 | G29: Independent Engineering Student | H29: Strong RTL + FPGA + measurement discipline. | I29: A3-P* | J29: Optimize pipeline and explain performance trade-offs. | K29: Architecture; RTL; verification; FPGA; LUT/FF/DSP/Fmax/latency/throughput analysis. | L29: Reference model; 2+ pipeline configurations; RTL + verification; Fmax/resource/latency/throughput table; Kết luận về pipeline trade-off. | M29: Compare two pipeline depths/architectures. | N29: Python/MATLAB, Verilog, simulator, FPGA tool. | O29: active | P29: A5 | Q29: FPGA system engineer.
A30: A3-T02 | B30: A3 | C30: T | D30: Hardware/software co-verification cho hệ thống FPGA | E30: Hardware/Software Co-Verification for an FPGA System | F30: 2 | G30: Independent Engineering Student | H30: Python/MATLAB + RTL + FPGA. | I30: A3-P* | J30: Build repeatable software-vs-hardware validation. | K30: Golden model; vector generation; RTL/FPGA agreement; automated comparison; report. | L30: Golden model + sinh vector tự động + so khớp RTL/FPGA tự động trên tối thiểu một IP, kèm báo cáo mismatch tái lập được. | M30: Regression automation. | N30: FPGA vendor tools; Verilog/SystemVerilog; ModelSim/Questa/Icarus/Verilator tùy nền tảng; logic analyzer khi có. | O30: active | Q30: FPGA system engineer.
A31: A4-P01 | B31: A4 | C31: P | D31: Làm quen RTL-to-Gates bằng Yosys | E31: RTL-to-Gates Exploration with Yosys | F31: 1 | G31: Beginner Engineer | H31: RTL cơ bản; Linux cơ bản. | J31: Observe how RTL becomes logic cells/netlist. | K31: RTL; synthesis script; netlist/report; explanation. | M31: Coding-style comparison. | N31: WSL/Linux; Yosys; LibreLane/OpenROAD; KLayout; PDK phù hợp (ví dụ Sky130 khi dùng open-source flow). | O31: active | Q31: ASIC physical design; RTL-to-GDSII engineer.
A32: A4-P02 | B32: A4 | C32: P | D32: Khảo sát ảnh hưởng của RTL coding style tới synthesis | E32: Effect of RTL Coding Style on Synthesis Results | F32: 2 | G32: Independent Engineering Student | H32: RTL + Yosys basics. | I32: A4-P01 | J32: Control one variable at a time and compare mapping/timing/area proxy. | K32: Equivalent RTL variants; synthesis evidence; comparison. | M32: Add STA/technology mapping. | N32: WSL/Linux; Yosys; LibreLane/OpenROAD; KLayout; PDK phù hợp (ví dụ Sky130 khi dùng open-source flow). | O32: active | Q32: ASIC physical design; RTL-to-GDSII engineer.
A33: A4-I01 | B33: A4 | C33: I | D33: Xây dựng môi trường RTL-to-GDSII mã nguồn mở | E33: Build an Open-Source RTL-to-GDSII Environment | F33: 2 | G33: Independent Engineering Student | H33: Linux/WSL; Git; RTL basics. | J33: WSL/Linux -> Nix/managed environment -> LibreLane/OpenROAD -> KLayout. | K33: Reproducible setup; sample designs; documented commands; troubleshooting notes. | M33: CI smoke test; version pinning. | N33: WSL/Linux; Yosys; LibreLane/OpenROAD; KLayout; PDK phù hợp (ví dụ Sky130 khi dùng open-source flow). | O33: active | Q33: ASIC physical design; RTL-to-GDSII engineer.
A34: A4-T01 | B34: A4 | C34: T | D34: Thiết kế một Digital IP từ RTL đến GDSII | E34: Design and Evaluation of a Digital IP from RTL to GDSII | F34: 2 | G34: Independent Engineering Student | H34: Verified RTL + Linux + synthesis basics. | I34: A4-P01 | J34: End-to-end digital ASIC flow on a manageable IP. | K34: Spec; RTL; testbench; synthesis; STA; physical implementation; DRC/LVS evidence; GDSII; PPA report. | L34: Specification + block diagram; RTL + testbench + regression; Waveform/log verification; Synthesis/STA/PPA report; Layout/GDSII hoặc physical implementation report; Repository có README và hướng dẫn tái lập. | M34: Compare constraints or architectures only after baseline sign-off. | N34: Verilog/SystemVerilog, Icarus/Verilator, GTKWave, Yosys, LibreLane/OpenROAD, KLayout, Git. | O34: active | P34: A1 | Q34: ASIC physical design; RTL-to-GDSII engineer.
A35: A4-T02 | B35: A4 | C35: T | D35: Khảo sát ảnh hưởng kiến trúc RTL đến PPA | E35: RTL Architecture Exploration for PPA | F35: 3 | G35: Research-Ready Undergraduate | H35: A4-T01-level flow on at least one design. | I35: A4-T01 | J35: Measure power/performance/area proxies and explain architectural causes. | K35: 2+ functionally equivalent architectures; controlled PPA comparison; analysis. | L35: Hai hoặc nhiều RTL architecture; Testbench dùng chung; Bảng PPA + latency/throughput; Giải thích nguyên nhân vật lý/kiến trúc của khác biệt; Khuyến nghị architecture theo mục tiêu thiết kế. | M35: Pareto optimization. | N35: Verilog/SystemVerilog, simulator, Yosys/EDA synthesis, OpenSTA/ASIC flow, Python/Excel để phân tích. | O35: active | P35: A2 | Q35: ASIC physical design; RTL-to-GDSII engineer.
A36: A4-R01 | B36: A4 | C36: R | D36: Design-space exploration cho một Digital IP | E36: Design-Space Exploration for a Digital IP | F36: 4 | G36: Undergraduate Researcher | H36: Reproducible ASIC flow + scripting + research readiness. | I36: A4-T01 | J36: Search architecture/constraint space for PPA trade-offs. | K36: Automated experiments; statistical/controlled analysis; research report. | M36: Optimization algorithm if justified. | N36: WSL/Linux; Yosys; LibreLane/OpenROAD; KLayout; PDK phù hợp (ví dụ Sky130 khi dùng open-source flow). | O36: active | Q36: ASIC physical design; RTL-to-GDSII engineer.
A37: A5-P01 | B37: A5 | C37: P | D37: Xây dựng testbench có hệ thống cho một RTL module | E37: Systematic Testbench Development for an RTL Module | F37: 1 | G37: Beginner Engineer | H37: RTL + simulation. | J37: Normal/boundary/invalid/reset tests. | K37: Test plan; testbench; pass/fail evidence; bug log. | M37: Assertions/checkers. | N37: Git/GitHub; shell/Python; Icarus/Verilator; Yosys; LibreLane/Nix; CI phù hợp. | O37: active | Q37: Verification/EDA infrastructure; DevOps cho phần cứng.
A38: A5-P02 | B38: A5 | C38: P | D38: Regression testing cho Digital IP | E38: Regression Testing for a Digital IP | F38: 2 | G38: Independent Engineering Student | H38: A5-P01 + scripting. | I38: A5-P01 | J38: Automate repeated simulation and failure reporting. | K38: Regression script; test set; summary report; reproducible run. | M38: CI integration. | N38: Git/GitHub; shell/Python; Icarus/Verilator; Yosys; LibreLane/Nix; CI phù hợp. | O38: active | Q38: Verification/EDA infrastructure; DevOps cho phần cứng.
A39: A5-I01 | B39: A5 | C39: I | D39: Xây dựng Git workflow cho dự án RTL | E39: Git Workflow for RTL Projects | F39: 1 | G39: Beginner Engineer | H39: Git basics desirable. | J39: Practice reproducible collaboration on a small RTL project. | K39: Repo structure; branches/issues; README; test scripts; contribution guide. | M39: Pull-request checks. | N39: Git/GitHub; shell/Python; Icarus/Verilator; Yosys; LibreLane/Nix; CI phù hợp. | O39: active | Q39: Verification/EDA infrastructure; DevOps cho phần cứng.
A40: A5-T01 | B40: A5 | C40: T | D40: Xây dựng quy trình ASIC tái lập sử dụng LibreLane + Nix | E40: Reproducible ASIC Workflow Using LibreLane and Nix | F40: 3 | G40: Research-Ready Undergraduate | H40: Linux + Git + A4 basics. | I40: A4-P01 | J40: Reproducibility is the thesis object, not software installation alone. | K40: Pinned environment; 3 reference designs; repeatability evidence; docs; troubleshooting. | L40: Repository môi trường; Automated scripts; 3 benchmark designs; Reproducibility checklist; Installation/use guide; Báo cáo đánh giá workflow. | M40: Docker fallback/CI comparison if needed. | N40: WSL/Linux, Git, Nix, LibreLane/OpenROAD, Yosys, simulators. | O40: active | P40: A6 | Q40: Verification/EDA infrastructure; DevOps cho phần cứng.
...

Sheet Students
A1: Student ID | B1: Full name | C1: Class | D1: Email | E1: Career goal | F1: Track Type | G1: Top 1 | H1: Top 2 | I1: Top 3 | J1: Status | K1: Risk | L1: Assigned Topic | M1: MVT | N1: Extension | O1: Last Evidence | P1: Next Deliverable | Q1: Next Deadline | R1: Notes

Sheet Readiness
A1: Student ID | B1: Full name | C1: Electronics | D1: Digital Logic | E1: Verilog/SV | F1: Simulation/Debug | G1: FPGA | H1: Python | I1: MATLAB | J1: Linux/WSL | K1: Git/GitHub | L1: DSP | M1: Digital Comm | N1: Probability | O1: Coding Theory | P1: Polar Codes | Q1: English Reading | R1: Technical Writing | S1: TR Avg | T1: WR Commitment | U1: WR Persistence | V1: WR Integrity | W1: WR Initiative | X1: WR Critical Thinking | Y1: WR Total | Z1: RR Literature | AA1: RR Baseline | AB1: RR Experiment | AC1: RR Interpretation | AD1: RR Ownership | AE1: RR Avg | AF1: Mentor Decision | AG1: Conditions/Notes
S2: =IFERROR(AVERAGE(C2:R2),"") | Y2: =IF(COUNTA(T2:X2)=0,"",SUM(T2:X2)) | AE2: =IFERROR(AVERAGE(Z2:AD2),"")
S3: =IFERROR(AVERAGE(C3:R3),"") | Y3: =IF(COUNTA(T3:X3)=0,"",SUM(T3:X3)) | AE3: =IFERROR(AVERAGE(Z3:AD3),"")
S4: =IFERROR(AVERAGE(C4:R4),"") | Y4: =IF(COUNTA(T4:X4)=0,"",SUM(T4:X4)) | AE4: =IFERROR(AVERAGE(Z4:AD4),"")
S5: =IFERROR(AVERAGE(C5:R5),"") | Y5: =IF(COUNTA(T5:X5)=0,"",SUM(T5:X5)) | AE5: =IFERROR(AVERAGE(Z5:AD5),"")
S6: =IFERROR(AVERAGE(C6:R6),"") | Y6: =IF(COUNTA(T6:X6)=0,"",SUM(T6:X6)) | AE6: =IFERROR(AVERAGE(Z6:AD6),"")
S7: =IFERROR(AVERAGE(C7:R7),"") | Y7: =IF(COUNTA(T7:X7)=0,"",SUM(T7:X7)) | AE7: =IFERROR(AVERAGE(Z7:AD7),"")
S8: =IFERROR(AVERAGE(C8:R8),"") | Y8: =IF(COUNTA(T8:X8)=0,"",SUM(T8:X8)) | AE8: =IFERROR(AVERAGE(Z8:AD8),"")
S9: =IFERROR(AVERAGE(C9:R9),"") | Y9: =IF(COUNTA(T9:X9)=0,"",SUM(T9:X9)) | AE9: =IFERROR(AVERAGE(Z9:AD9),"")
S10: =IFERROR(AVERAGE(C10:R10),"") | Y10: =IF(COUNTA(T10:X10)=0,"",SUM(T10:X10)) | AE10: =IFERROR(AVERAGE(Z10:AD10),"")
S11: =IFERROR(AVERAGE(C11:R11),"") | Y11: =IF(COUNTA(T11:X11)=0,"",SUM(T11:X11)) | AE11: =IFERROR(AVERAGE(Z11:AD11),"")
S12: =IFERROR(AVERAGE(C12:R12),"") | Y12: =IF(COUNTA(T12:X12)=0,"",SUM(T12:X12)) | AE12: =IFERROR(AVERAGE(Z12:AD12),"")
S13: =IFERROR(AVERAGE(C13:R13),"") | Y13: =IF(COUNTA(T13:X13)=0,"",SUM(T13:X13)) | AE13: =IFERROR(AVERAGE(Z13:AD13),"")
... S101: =IFERROR(AVERAGE(C101:R101),"") | Y101: =IF(COUNTA(T101:X101)=0,"",SUM(T101:X101)) | AE101: =IFERROR(AVERAGE(Z101:AD101),"")

Sheet Weekly_Status
A1: Student ID | B1: Full name | C1: Week | D1: Date | E1: Goal | F1: Completed | G1: Evidence Link | H1: Failure/Blocker | I1: Diagnosis | J1: What Tried | K1: Proposed Next Step | L1: Question for Mentor | M1: AI Use Summary | N1: Risk | O1: Mentor Decision | P1: Next Deliverable | Q1: Deadline

Sheet Milestones
A1: Student ID | B1: Full name | C1: Assigned Topic | D1: Gate | E1: Week Window | F1: Requirement | G1: Status | H1: Evidence | I1: Decision/Action | J1: Reviewed Date
D2: Gate 1 - Problem & Foundation | E2: Tuần 1-2 | F2: Hiểu problem, input/output, baseline, metric, prerequisite gaps. | G2: Not Started
D3: Gate 2 - Baseline | E3: Tuần 3-5 | F3: Baseline/chức năng cơ sở phải chạy và có evidence tái lập. | G3: Not Started
D4: Gate 3 - Core Implementation | E4: Tuần 6-8 | F4: Có core implementation và kết quả định lượng trung gian. | G4: Not Started
D5: Gate 4 - Experiments | E5: Tuần 9-11 | F5: Thực nghiệm chính hoàn tất; table/figure chính hình thành. | G5: Not Started
D6: Gate 5 - Analysis & Draft | E6: Tuần 12-13 | F6: Phân tích kết quả và bản thảo báo cáo/khóa luận đầy đủ. | G6: Not Started
D7: Gate 6 - Reproducibility & Defense | E7: Tuần 14-15 | F7: Người khác có thể chạy lại; slides/demo; legacy package; defense readiness. | G7: Not Started
D8: Gate 1 - Problem & Foundation | E8: Tuần 1-2 | F8: Hiểu problem, input/output, baseline, metric, prerequisite gaps. | G8: Not Started
D9: Gate 2 - Baseline | E9: Tuần 3-5 | F9: Baseline/chức năng cơ sở phải chạy và có evidence tái lập. | G9: Not Started
D10: Gate 3 - Core Implementation | E10: Tuần 6-8 | F10: Có core implementation và kết quả định lượng trung gian. | G10: Not Started
D11: Gate 4 - Experiments | E11: Tuần 9-11 | F11: Thực nghiệm chính hoàn tất; table/figure chính hình thành. | G11: Not Started
D12: Gate 5 - Analysis & Draft | E12: Tuần 12-13 | F12: Phân tích kết quả và bản thảo báo cáo/khóa luận đầy đủ. | G12: Not Started
D13: Gate 6 - Reproducibility & Defense | E13: Tuần 14-15 | F13: Người khác có thể chạy lại; slides/demo; legacy package; defense readiness. | G13: Not Started
... D601: Gate 6 - Reproducibility & Defense | E601: Tuần 14-15 | F601: Người khác có thể chạy lại; slides/demo; legacy package; defense readiness. | G601: Not Started

Sheet Rubrics
A1: WORKING READINESS (0-4 each) | F1: SUGGESTED THRESHOLDS
A3: Criterion | B3: Evidence | C3: Score | D3: Notes | F3: Activity | G3: TR | H3: WR | I3: RR | J3: Interpretation
A4: Cam kết & kỷ luật | B4: Đúng deadline; tham gia/đổi lịch đúng quy ước; cập nhật đều; không để task “vâng dạ rồi để đó”. | C4: 0-4 | F4: Course Project | G4: Low-Medium | H4: >=10/20 | I4: Not required | J4: Skill acquisition
A5: Kiên trì | B5: Khi gặp lỗi có evidence về các thử nghiệm chẩn đoán, không bỏ cuộc ngay. | C5: 0-4 | F5: Internship | G5: Medium | H5: >=12/20 | I5: Not required | J5: Engineering workflow
A6: Trung thực | B6: Phân biệt rõ tự làm, tham khảo, AI hỗ trợ, chưa hiểu, kết quả âm/không như kỳ vọng. | C6: 0-4 | F6: DATN Engineering | G6: Medium | H6: >=14/20 | I6: Basic | J6: Complete engineering project
A7: Chủ động | B7: Tự tìm từ khóa/tài liệu; đề xuất next step trước khi hỏi mentor “em làm gì tiếp?”. | C7: 0-4 | F7: DATN Research-oriented | G7: Good | H7: >=15/20 | I7: Good | J7: Experiment/research orientation
A8: Tư duy phản biện | B8: Hỏi tại sao; so sánh alternatives; chấp nhận/sửa quan điểm theo evidence. | C8: 0-4 | F8: Research | G8: Good+ | H8: >=16/20 | I8: Required | J8: Research question ownership
F9: Advanced B6/AB-R | G9: High | H9: >=17/20 | I9: Very good | J9: Advanced co-design/research
A11: RESEARCH READINESS (0-4 each)
A13: Criterion | B13: Evidence | C13: Score | D13: Notes
A14: Literature comprehension | B14: Đọc được paper/tài liệu và tách problem, assumptions, method, metrics, limitations. | C14: 0-4
A15: Baseline discipline | B15: Ưu tiên baseline đúng, tái lập trước novelty. | C15: 0-4
A16: Experimental design | B16: Biết control variables, seed/config, metric và so sánh công bằng. | C16: 0-4
A17: Interpretation | B17: Giải thích kết quả, không chỉ báo số/figure. | C17: 0-4
A18: Research ownership | B18: Tự hình thành câu hỏi/giả thuyết nhỏ và biết giới hạn claim. | C18: 0-4
A22: NGUỒN CHUẨN: 06_Data/readiness_rubrics.json (phiên bản hiện hành — xem meta.version) — WR 0-4 (/20) với ngưỡng; RR 0-4; TR 0-5 với 16 năng lực. Sheet này là view.

Sheet Dashboard
A1: MENTORING PROGRAM DASHBOARD - TEMPLATE
A3: KPI | B3: Value | D3: Program rule | E3: Status
A4: Total students | B4: =COUNTA(Students!A2:A101) -> 0 | D4: Single source of truth | E4: 06_Data/
A5: Active | B5: =COUNTIF(Students!J2:J101,"Active") -> 0 | D5: Baseline before novelty | E5: Required
A6: Yellow risk | B6: =COUNTIF(Students!K2:K101,"Yellow") -> 0 | D6: Gate 3 miss | E6: Reduce scope
A7: Red risk | B7: =COUNTIF(Students!K2:K101,"Red") -> 0 | D7: AI rule | E7: Cannot explain = Not completed
A8: Research track | B8: =COUNTIF(Students!F2:F101,"R") -> 0 | D8: Legacy package | E8: Required
A10: How to use
A11: 1) Add students. 2) Score readiness. 3) Track weekly evidence. 4) Review Gate 1-6. 5) Keep this workbook private when it contains real student data.

Sheet Instructions
A1: MENTORING MANAGEMENT WORKBOOK - INSTRUCTIONS
A3: Sheet | B3: Use
A4: Dashboard | B4: Quick program status.
A5: Portfolio | B5: Read-only master topic view from canonical project data.
A6: Students | B6: Private cohort roster, assignment, risk, next action.
A7: Readiness | B7: TR/WR/RR scoring and mentor decision.
A8: Weekly_Status | B8: One row per student-week with evidence and next step.
A9: Milestones | B9: Gate 1-6 records.
A10: Rubrics | B10: Scoring anchors and thresholds.
A12: PRIVACY: Do not publish this workbook when it contains real names, emails, readiness scores, warnings or mentor notes. Public catalogs and private operational records must remain separate.
A17: v1.5.1 (23/08/2026): Portfolio = view sinh từ 06_Data (105 đề tài, có MVT/Status/Alias). Khi có dữ liệu SV thật, lưu bản sao vào 07_Private/ và không chia sẻ file này.
